Workbook

Sheet Assumptions
A1: INSTITUTIONAL PAYMENT SETTLEMENT FLOAT & 13W CASH FLOW ENGINE
A2: Dynamic Treasury Financial Model | Core Assumptions, Policy Constants & Scenario Matrix
A4: 1. GLOBAL TREASURY POLICY CONSTANTS & FACILITY PARAMETERS
A5: Base Daily Gross Payment Volume (GPV) | C5: 600000000 | D5: Platform daily auth baseline
A6: Model Projection Horizon (Days) | C6: 150 | D6: Active projection calendar horizon
A7: Annualized Scale Run-Rate | C7: =C5*C6 | D7: Annualized GPV = Daily GPV * Horizon
A8: Actual/360 Money Market Day Count Basis | C8: 360 | D8: Institutional money market convention
A9: Revolving Credit Facility Capacity (Cmax) | C9: 500000000 | D9: Total bilateral bank facility
A10: Minimum Liquidity Covenant Floor (Lmin) | C10: 250000000 | D10: Credit agreement minimum liquidity floor
A11: Target Liquidity Sweep Threshold (Ltarget) | C11: 300000000 | D11: Automatic debt repayment sweep trigger
A12: Covenant Headroom Early Warning Alert Trigger | C12: 50000000 | D12: Headroom alert threshold below covenant floor
A13: Initial Corporate Opening Cash Balance | C13: 300000000 | D13: Day 1 starting operational cash
A14: Initial Safeguarded Client Pool Balance | C14: 0 | D14: Day 1 starting client pool (zero commingling)
A15: Initial Active Revolver Debt Balance | C15: 0 | D15: Day 1 starting facility borrowing
A16: Active Macro Scenario Selector | C16: BASELINE | D16: Active macroeconomic environment
A17: Benchmark Base SOFR Rate | C17: 0.0425 | D17: Secured Overnight Financing Rate
A18: Credit Facility Margin Spread | C18: 0.02 | D18: Bank credit facility spread
A19: All-in Borrowing Rate (SOFR + Spread) | C19: =C17+C18 | D19: Effective annual borrowing rate
A20: CECL Annual Probability of Default (PD) | C20: 0.002 | D20: Expected loss probability proxy
A21: CECL Loss Given Default (LGD) | C21: 0.5 | D21: Expected severity on default
A22: Basel III Stressed 30-Day Outflow Run-off Overlay | C22: 0.3 | D22: Stressed run-off overlay
A23: Basel III LCR Warning Band Threshold | C23: 1.05 | D23: LCR early warning buffer (105%)
A24: Basel III LCR Minimum Regulatory Floor | C24: 1 | D24: Statutory minimum compliant floor (100%)
A26: 2. PAYMENT NETWORK CLEARING & TAKE-RATE STRUCTURE
A27: Payment Rail | B27: Share of GPV | C27: Processor Take Rate | D27: Interchange / Scheme Cost | E27: Net Processor Spread | F27: Clearing Lag
A28: CARD_VISA | B28: 0.44 | C28: 0.0275 | D28: 0.018 | E28: =C28-D28 | F28: T+2 (2 days)
A29: CARD_MC | B29: 0.3 | C29: 0.0275 | D29: 0.0185 | E29: =C29-D29 | F29: T+2 (2 days)
A30: CARD_AMEX | B30: 0.15 | C30: 0.0315 | D30: 0.022 | E30: =C30-D30 | F30: T+3 (3 days)
A31: ACH_STANDARD | B31: 0.07 | C31: 0.008 | D31: 0.002 | E31: =C31-D31 | F31: T+3 (3 days)
A32: ACH_SAME_DAY | B32: 0.03 | C32: 0.008 | D32: 0.002 | E32: =C32-D32 | F32: T+1 (1 days)
A33: RTP_FEDNOW | B33: 0.01 | C33: 0.005 | D33: 0.001 | E33: =C33-D33 | F33: T+0 (0 days)
A35: 3. MACROECONOMIC STRESS SCENARIO MATRIX
A36: Scenario Name | B36: Benchmark SOFR | C36: Credit Spread | D36: All-in Borrowing Rate | E36: CECL PD Rate | F36: CECL LGD Rate | G36: Timing Lag Shift
A37: BASELINE | B37: 0.0425 | C37: 0.02 | D37: =B37+C37 | E37: 0.002 | F37: 0.5 | G37: Standard T+1..T+3
A38: ADVERSE | B38: 0.0575 | C38: 0.0275 | D38: =B38+C38 | E38: 0.011 | F38: 0.7 | G38: +24h Holiday Lag
A39: SEVERELY_ADVERSE | B39: 0.07 | C39: 0.0375 | D39: =B39+C39 | E39: 0.035 | F39: 0.85 | G39: +48h Systemic Freeze
A41: 4. MODEL SUMMARY PERFORMANCE BENCHMARKS (DYNAMIC FORMULAS)
A42: Final Corporate Closing Cash | C42: ='Daily_Cash_Waterfall'!O151 | D42: Ending unrestricted operating cash
A43: Peak Revolver Facility Utilization | C43: =MAX('Daily_Cash_Waterfall'!M2:M151) | D43: Maximum drawn credit balance
A44: Total Period Interest Expense Drag | C44: =SUM('Daily_Cash_Waterfall'!N2:N151) | D44: Total Actual/360 interest accrued
...

Sheet Data_Feed_Daily
A1: Ledger Date | B1: Authorized GPV ($) | C1: Inbound Settlements Gross ($) | D1: Scheme & Interchange Costs ($) | E1: Outbound Merchant Payouts Gross ($) | F1: Merchant Reserves Withheld ($) | G1: Net Processor Revenue Swept ($) | H1: Settlements Receivable Asset ($) | I1: Customers Payable Liability ($)
A2: 2026-01-01 | B2: 0 | C2: 0 | D2: 0 | E2: 0 | F2: 0 | G2: 0 | H2: 6.0548491e+08 | I2: 5.7142638e+08
A3: 2026-01-02 | B3: 6.5554473e+08 | C3: 31776040 | D3: 49940.587 | E3: 6.5554473e+08 | F3: 36874391 | G3: 5863847.6 | H3: 1.3293732e+09 | I3: 6.6591429e+08
A4: 2026-01-03 | B4: 0 | C4: 0 | D4: 0 | E4: 0 | F4: 0 | G4: 0 | H4: 2.1269338e+09 | I4: 1.4186121e+09
A5: 2026-01-04 | B5: 0 | C5: 0 | D5: 0 | E5: 0 | F5: 0 | G5: 0 | H5: 2.928943e+09 | I5: 2.1755083e+09
A6: 2026-01-05 | B6: 2.2261317e+09 | C6: 1.9891997e+09 | D6: 33923134 | E6: 2.2261317e+09 | F6: 1.2521991e+08 | G6: 19912748 | H6: 1.5046247e+09 | I6: 6.0770326e+08
A7: 2026-01-06 | B7: 6.4781712e+08 | C7: 7.9166219e+08 | D7: 13586331 | E7: 6.4781712e+08 | F7: 36439713 | G7: 5794724.1 | H7: 1.2895233e+09 | I7: 5.4045508e+08
A8: 2026-01-07 | B8: 5.8124775e+08 | C8: 6.1777407e+08 | D8: 10408480 | E8: 5.8124775e+08 | F8: 32695186 | G8: 5199261.2 | H8: 1.2740504e+09 | I8: 5.603242e+08
A9: 2026-01-08 | B9: 5.9105651e+08 | C9: 5.7494098e+08 | D9: 9751546.6 | E9: 5.9105651e+08 | F9: 33246929 | G9: 5287000.5 | H9: 1.293417e+09 | I9: 5.6339245e+08
A10: 2026-01-09 | B10: 6.5873854e+08 | C10: 5.981715e+08 | D10: 10139820 | E10: 6.5873854e+08 | F10: 37054043 | G10: 5892416.2 | H10: 1.4748524e+09 | I10: 6.7746192e+08
A11: 2026-01-10 | B11: 0 | C11: 0 | D11: 0 | E11: 0 | F11: 0 | G11: 0 | H11: 2.2348911e+09 | I11: 1.3947485e+09
A12: 2026-01-11 | B12: 0 | C12: 0 | D12: 0 | E12: 0 | F12: 0 | G12: 0 | H12: 3.035469e+09 | I12: 2.1502939e+09
A13: 2026-01-12 | B13: 2.2162646e+09 | C13: 2.1058457e+09 | D13: 35704692 | E13: 2.2162646e+09 | F13: 1.2466488e+08 | G13: 19824487 | H13: 1.5436236e+09 | I13: 6.3815696e+08
... A151: 2026-05-30 | B151: 0 | C151: 0 | D151: 0 | E151: 0 | F151: 0 | G151: 0 | H151: 2.2837127e+09 | I151: 1.4339899e+09

Sheet Daily_Cash_Waterfall
A1: Ledger Date | B1: Safeguarded Open Cash | C1: Inbound Settlements | D1: Outbound Payouts (Net) | E1: Net Operating Float | F1: Corp Subordination Injection | G1: Safeguarded Closing Cash | H1: Corporate Opening Cash | I1: Net Revenue Swept | J1: Pre-Financing Corp Cash | K1: Revolver Draw | L1: Revolver Repay | M1: Active Debt Balance | N1: Interest Expense (Act/360) | O1: Corporate Closing Cash | P1: Total Available Liquidity | Q1: Covenant Headroom | R1: Early Warning Status
A2: =Data_Feed_Daily!A2 | B2: =IF(ISNUMBER(G1), G1, Assumptions!$C$14) | C2: =Data_Feed_Daily!C2 | D2: =Data_Feed_Daily!E2-Data_Feed_Daily!F2 | E2: =C2-D2-Data_Feed_Daily!D2 | F2: =MAX(0, D2-(B2+C2)) | G2: =B2+C2-D2+F2 | H2: =IF(ISNUMBER(O1), O1, Assumptions!$C$13) | I2: =Data_Feed_Daily!G2 | J2: =H2+I2-F2 | K2: =IF(J2<Assumptions!$C$10, MIN(Assumptions!$C$10-J2, Assumptions!$C$9-IF(ISNUMBER(M1), M1, Assumptions!$C$15)), 0) | L2: =IF(AND(J2>Assumptions!$C$11, IF(ISNUMBER(M1), M1, Assumptions!$C$15)>0), MIN(J2-Assumptions!$C$11, IF(ISNUMBER(M1), M1, Assumptions!$C$15)), 0) | M2: =IF(ISNUMBER(M1), M1, Assumptions!$C$15)+K2-L2 | N2: =ROUND(M2*(Assumptions!$C$19/Assumptions!$C$8), 2) | O2: =J2+K2-L2-N2 | P2: =O2+(Assumptions!$C$9-M2) | Q2: =P2-Assumptions!$C$10 | R2: =IF(Q2<Assumptions!$C$12, "ALERT TRIGGERED", "COMPLIANT")
A3: =Data_Feed_Daily!A3 | B3: =IF(ISNUMBER(G2), G2, Assumptions!$C$14) | C3: =Data_Feed_Daily!C3 | D3: =Data_Feed_Daily!E3-Data_Feed_Daily!F3 | E3: =C3-D3-Data_Feed_Daily!D3 | F3: =MAX(0, D3-(B3+C3)) | G3: =B3+C3-D3+F3 | H3: =IF(ISNUMBER(O2), O2, Assumptions!$C$13) | I3: =Data_Feed_Daily!G3 | J3: =H3+I3-F3 | K3: =IF(J3<Assumptions!$C$10, MIN(Assumptions!$C$10-J3, Assumptions!$C$9-IF(ISNUMBER(M2), M2, Assumptions!$C$15)), 0) | L3: =IF(AND(J3>Assumptions!$C$11, IF(ISNUMBER(M2), M2, Assumptions!$C$15)>0), MIN(J3-Assumptions!$C$11, IF(ISNUMBER(M2), M2, Assumptions!$C$15)), 0) | M3: =IF(ISNUMBER(M2), M2, Assumptions!$C$15)+K3-L3 | N3: =ROUND(M3*(Assumptions!$C$19/Assumptions!$C$8), 2) | O3: =J3+K3-L3-N3 | P3: =O3+(Assumptions!$C$9-M3) | Q3: =P3-Assumptions!$C$10 | R3: =IF(Q3<Assumptions!$C$12, "ALERT TRIGGERED", "COMPLIANT")
A4: =Data_Feed_Daily!A4 | B4: =IF(ISNUMBER(G3), G3, Assumptions!$C$14) | C4: =Data_Feed_Daily!C4 | D4: =Data_Feed_Daily!E4-Data_Feed_Daily!F4 | E4: =C4-D4-Data_Feed_Daily!D4 | F4: =MAX(0, D4-(B4+C4)) | G4: =B4+C4-D4+F4 | H4: =IF(ISNUMBER(O3), O3, Assumptions!$C$13) | I4: =Data_Feed_Daily!G4 | J4: =H4+I4-F4 | K4: =IF(J4<Assumptions!$C$10, MIN(Assumptions!$C$10-J4, Assumptions!$C$9-IF(ISNUMBER(M3), M3, Assumptions!$C$15)), 0) | L4: =IF(AND(J4>Assumptions!$C$11, IF(ISNUMBER(M3), M3, Assumptions!$C$15)>0), MIN(J4-Assumptions!$C$11, IF(ISNUMBER(M3), M3, Assumptions!$C$15)), 0) | M4: =IF(ISNUMBER(M3), M3, Assumptions!$C$15)+K4-L4 | N4: =ROUND(M4*(Assumptions!$C$19/Assumptions!$C$8), 2) | O4: =J4+K4-L4-N4 | P4: =O4+(Assumptions!$C$9-M4) | Q4: =P4-Assumptions!$C$10 | R4: =IF(Q4<Assumptions!$C$12, "ALERT TRIGGERED", "COMPLIANT")
A5: =Data_Feed_Daily!A5 | B5: =IF(ISNUMBER(G4), G4, Assumptions!$C$14) | C5: =Data_Feed_Daily!C5 | D5: =Data_Feed_Daily!E5-Data_Feed_Daily!F5 | E5: =C5-D5-Data_Feed_Daily!D5 | F5: =MAX(0, D5-(B5+C5)) | G5: =B5+C5-D5+F5 | H5: =IF(ISNUMBER(O4), O4, Assumptions!$C$13) | I5: =Data_Feed_Daily!G5 | J5: =H5+I5-F5 | K5: =IF(J5<Assumptions!$C$10, MIN(Assumptions!$C$10-J5, Assumptions!$C$9-IF(ISNUMBER(M4), M4, Assumptions!$C$15)), 0) | L5: =IF(AND(J5>Assumptions!$C$11, IF(ISNUMBER(M4), M4, Assumptions!$C$15)>0), MIN(J5-Assumptions!$C$11, IF(ISNUMBER(M4), M4, Assumptions!$C$15)), 0) | M5: =IF(ISNUMBER(M4), M4, Assumptions!$C$15)+K5-L5 | N5: =ROUND(M5*(Assumptions!$C$19/Assumptions!$C$8), 2) | O5: =J5+K5-L5-N5 | P5: =O5+(Assumptions!$C$9-M5) | Q5: =P5-Assumptions!$C$10 | R5: =IF(Q5<Assumptions!$C$12, "ALERT TRIGGERED", "COMPLIANT")
A6: =Data_Feed_Daily!A6 | B6: =IF(ISNUMBER(G5), G5, Assumptions!$C$14) | C6: =Data_Feed_Daily!C6 | D6: =Data_Feed_Daily!E6-Data_Feed_Daily!F6 | E6: =C6-D6-Data_Feed_Daily!D6 | F6: =MAX(0, D6-(B6+C6)) | G6: =B6+C6-D6+F6 | H6: =IF(ISNUMBER(O5), O5, Assumptions!$C$13) | I6: =Data_Feed_Daily!G6 | J6: =H6+I6-F6 | K6: =IF(J6<Assumptions!$C$10, MIN(Assumptions!$C$10-J6, Assumptions!$C$9-IF(ISNUMBER(M5), M5, Assumptions!$C$15)), 0) | L6: =IF(AND(J6>Assumptions!$C$11, IF(ISNUMBER(M5), M5, Assumptions!$C$15)>0), MIN(J6-Assumptions!$C$11, IF(ISNUMBER(M5), M5, Assumptions!$C$15)), 0) | M6: =IF(ISNUMBER(M5), M5, Assumptions!$C$15)+K6-L6 | N6: =ROUND(M6*(Assumptions!$C$19/Assumptions!$C$8), 2) | O6: =J6+K6-L6-N6 | P6: =O6+(Assumptions!$C$9-M6) | Q6: =P6-Assumptions!$C$10 | R6: =IF(Q6<Assumptions!$C$12, "ALERT TRIGGERED", "COMPLIANT")
A7: =Data_Feed_Daily!A7 | B7: =IF(ISNUMBER(G6), G6, Assumptions!$C$14) | C7: =Data_Feed_Daily!C7 | D7: =Data_Feed_Daily!E7-Data_Feed_Daily!F7 | E7: =C7-D7-Data_Feed_Daily!D7 | F7: =MAX(0, D7-(B7+C7)) | G7: =B7+C7-D7+F7 | H7: =IF(ISNUMBER(O6), O6, Assumptions!$C$13) | I7: =Data_Feed_Daily!G7 | J7: =H7+I7-F7 | K7: =IF(J7<Assumptions!$C$10, MIN(Assumptions!$C$10-J7, Assumptions!$C$9-IF(ISNUMBER(M6), M6, Assumptions!$C$15)), 0) | L7: =IF(AND(J7>Assumptions!$C$11, IF(ISNUMBER(M6), M6, Assumptions!$C$15)>0), MIN(J7-Assumptions!$C$11, IF(ISNUMBER(M6), M6, Assumptions!$C$15)), 0) | M7: =IF(ISNUMBER(M6), M6, Assumptions!$C$15)+K7-L7 | N7: =ROUND(M7*(Assumptions!$C$19/Assumptions!$C$8), 2) | O7: =J7+K7-L7-N7 | P7: =O7+(Assumptions!$C$9-M7) | Q7: =P7-Assumptions!$C$10 | R7: =IF(Q7<Assumptions!$C$12, "ALERT TRIGGERED", "COMPLIANT")
A8: =Data_Feed_Daily!A8 | B8: =IF(ISNUMBER(G7), G7, Assumptions!$C$14) | C8: =Data_Feed_Daily!C8 | D8: =Data_Feed_Daily!E8-Data_Feed_Daily!F8 | E8: =C8-D8-Data_Feed_Daily!D8 | F8: =MAX(0, D8-(B8+C8)) | G8: =B8+C8-D8+F8 | H8: =IF(ISNUMBER(O7), O7, Assumptions!$C$13) | I8: =Data_Feed_Daily!G8 | J8: =H8+I8-F8 | K8: =IF(J8<Assumptions!$C$10, MIN(Assumptions!$C$10-J8, Assumptions!$C$9-IF(ISNUMBER(M7), M7, Assumptions!$C$15)), 0) | L8: =IF(AND(J8>Assumptions!$C$11, IF(ISNUMBER(M7), M7, Assumptions!$C$15)>0), MIN(J8-Assumptions!$C$11, IF(ISNUMBER(M7), M7, Assumptions!$C$15)), 0) | M8: =IF(ISNUMBER(M7), M7, Assumptions!$C$15)+K8-L8 | N8: =ROUND(M8*(Assumptions!$C$19/Assumptions!$C$8), 2) | O8: =J8+K8-L8-N8 | P8: =O8+(Assumptions!$C$9-M8) | Q8: =P8-Assumptions!$C$10 | R8: =IF(Q8<Assumptions!$C$12, "ALERT TRIGGERED", "COMPLIANT")
A9: =Data_Feed_Daily!A9 | B9: =IF(ISNUMBER(G8), G8, Assumptions!$C$14) | C9: =Data_Feed_Daily!C9 | D9: =Data_Feed_Daily!E9-Data_Feed_Daily!F9 | E9: =C9-D9-Data_Feed_Daily!D9 | F9: =MAX(0, D9-(B9+C9)) | G9: =B9+C9-D9+F9 | H9: =IF(ISNUMBER(O8), O8, Assumptions!$C$13) | I9: =Data_Feed_Daily!G9 | J9: =H9+I9-F9 | K9: =IF(J9<Assumptions!$C$10, MIN(Assumptions!$C$10-J9, Assumptions!$C$9-IF(ISNUMBER(M8), M8, Assumptions!$C$15)), 0) | L9: =IF(AND(J9>Assumptions!$C$11, IF(ISNUMBER(M8), M8, Assumptions!$C$15)>0), MIN(J9-Assumptions!$C$11, IF(ISNUMBER(M8), M8, Assumptions!$C$15)), 0) | M9: =IF(ISNUMBER(M8), M8, Assumptions!$C$15)+K9-L9 | N9: =ROUND(M9*(Assumptions!$C$19/Assumptions!$C$8), 2) | O9: =J9+K9-L9-N9 | P9: =O9+(Assumptions!$C$9-M9) | Q9: =P9-Assumptions!$C$10 | R9: =IF(Q9<Assumptions!$C$12, "ALERT TRIGGERED", "COMPLIANT")
A10: =Data_Feed_Daily!A10 | B10: =IF(ISNUMBER(G9), G9, Assumptions!$C$14) | C10: =Data_Feed_Daily!C10 | D10: =Data_Feed_Daily!E10-Data_Feed_Daily!F10 | E10: =C10-D10-Data_Feed_Daily!D10 | F10: =MAX(0, D10-(B10+C10)) | G10: =B10+C10-D10+F10 | H10: =IF(ISNUMBER(O9), O9, Assumptions!$C$13) | I10: =Data_Feed_Daily!G10 | J10: =H10+I10-F10 | K10: =IF(J10<Assumptions!$C$10, MIN(Assumptions!$C$10-J10, Assumptions!$C$9-IF(ISNUMBER(M9), M9, Assumptions!$C$15)), 0) | L10: =IF(AND(J10>Assumptions!$C$11, IF(ISNUMBER(M9), M9, Assumptions!$C$15)>0), MIN(J10-Assumptions!$C$11, IF(ISNUMBER(M9), M9, Assumptions!$C$15)), 0) | M10: =IF(ISNUMBER(M9), M9, Assumptions!$C$15)+K10-L10 | N10: =ROUND(M10*(Assumptions!$C$19/Assumptions!$C$8), 2) | O10: =J10+K10-L10-N10 | P10: =O10+(Assumptions!$C$9-M10) | Q10: =P10-Assumptions!$C$10 | R10: =IF(Q10<Assumptions!$C$12, "ALERT TRIGGERED", "COMPLIANT")
A11: =Data_Feed_Daily!A11 | B11: =IF(ISNUMBER(G10), G10, Assumptions!$C$14) | C11: =Data_Feed_Daily!C11 | D11: =Data_Feed_Daily!E11-Data_Feed_Daily!F11 | E11: =C11-D11-Data_Feed_Daily!D11 | F11: =MAX(0, D11-(B11+C11)) | G11: =B11+C11-D11+F11 | H11: =IF(ISNUMBER(O10), O10, Assumptions!$C$13) | I11: =Data_Feed_Daily!G11 | J11: =H11+I11-F11 | K11: =IF(J11<Assumptions!$C$10, MIN(Assumptions!$C$10-J11, Assumptions!$C$9-IF(ISNUMBER(M10), M10, Assumptions!$C$15)), 0) | L11: =IF(AND(J11>Assumptions!$C$11, IF(ISNUMBER(M10), M10, Assumptions!$C$15)>0), MIN(J11-Assumptions!$C$11, IF(ISNUMBER(M10), M10, Assumptions!$C$15)), 0) | M11: =IF(ISNUMBER(M10), M10, Assumptions!$C$15)+K11-L11 | N11: =ROUND(M11*(Assumptions!$C$19/Assumptions!$C$8), 2) | O11: =J11+K11-L11-N11 | P11: =O11+(Assumptions!$C$9-M11) | Q11: =P11-Assumptions!$C$10 | R11: =IF(Q11<Assumptions!$C$12, "ALERT TRIGGERED", "COMPLIANT")
A12: =Data_Feed_Daily!A12 | B12: =IF(ISNUMBER(G11), G11, Assumptions!$C$14) | C12: =Data_Feed_Daily!C12 | D12: =Data_Feed_Daily!E12-Data_Feed_Daily!F12 | E12: =C12-D12-Data_Feed_Daily!D12 | F12: =MAX(0, D12-(B12+C12)) | G12: =B12+C12-D12+F12 | H12: =IF(ISNUMBER(O11), O11, Assumptions!$C$13) | I12: =Data_Feed_Daily!G12 | J12: =H12+I12-F12 | K12: =IF(J12<Assumptions!$C$10, MIN(Assumptions!$C$10-J12, Assumptions!$C$9-IF(ISNUMBER(M11), M11, Assumptions!$C$15)), 0) | L12: =IF(AND(J12>Assumptions!$C$11, IF(ISNUMBER(M11), M11, Assumptions!$C$15)>0), MIN(J12-Assumptions!$C$11, IF(ISNUMBER(M11), M11, Assumptions!$C$15)), 0) | M12: =IF(ISNUMBER(M11), M11, Assumptions!$C$15)+K12-L12 | N12: =ROUND(M12*(Assumptions!$C$19/Assumptions!$C$8), 2) | O12: =J12+K12-L12-N12 | P12: =O12+(Assumptions!$C$9-M12) | Q12: =P12-Assumptions!$C$10 | R12: =IF(Q12<Assumptions!$C$12, "ALERT TRIGGERED", "COMPLIANT")
A13: =Data_Feed_Daily!A13 | B13: =IF(ISNUMBER(G12), G12, Assumptions!$C$14) | C13: =Data_Feed_Daily!C13 | D13: =Data_Feed_Daily!E13-Data_Feed_Daily!F13 | E13: =C13-D13-Data_Feed_Daily!D13 | F13: =MAX(0, D13-(B13+C13)) | G13: =B13+C13-D13+F13 | H13: =IF(ISNUMBER(O12), O12, Assumptions!$C$13) | I13: =Data_Feed_Daily!G13 | J13: =H13+I13-F13 | K13: =IF(J13<Assumptions!$C$10, MIN(Assumptions!$C$10-J13, Assumptions!$C$9-IF(ISNUMBER(M12), M12, Assumptions!$C$15)), 0) | L13: =IF(AND(J13>Assumptions!$C$11, IF(ISNUMBER(M12), M12, Assumptions!$C$15)>0), MIN(J13-Assumptions!$C$11, IF(ISNUMBER(M12), M12, Assumptions!$C$15)), 0) | M13: =IF(ISNUMBER(M12), M12, Assumptions!$C$15)+K13-L13 | N13: =ROUND(M13*(Assumptions!$C$19/Assumptions!$C$8), 2) | O13: =J13+K13-L13-N13 | P13: =O13+(Assumptions!$C$9-M13) | Q13: =P13-Assumptions!$C$10 | R13: =IF(Q13<Assumptions!$C$12, "ALERT TRIGGERED", "COMPLIANT")
... A151: =Data_Feed_Daily!A151 | B151: =IF(ISNUMBER(G150), G150, Assumptions!$C$14) | C151: =Data_Feed_Daily!C151 | D151: =Data_Feed_Daily!E151-Data_Feed_Daily!F151 | E151: =C151-D151-Data_Feed_Daily!D151 | F151: =MAX(0, D151-(B151+C151)) | G151: =B151+C151-D151+F151 | H151: =IF(ISNUMBER(O150), O150, Assumptions!$C$13) | I151: =Data_Feed_Daily!G151 | J151: =H151+I151-F151 | K151: =IF(J151<Assumptions!$C$10, MIN(Assumptions!$C$10-J151, Assumptions!$C$9-IF(ISNUMBER(M150), M150, Assumptions!$C$15)), 0) | L151: =IF(AND(J151>Assumptions!$C$11, IF(ISNUMBER(M150), M150, Assumptions!$C$15)>0), MIN(J151-Assumptions!$C$11, IF(ISNUMBER(M150), M150, Assumptions!$C$15)), 0) | M151: =IF(ISNUMBER(M150), M150, Assumptions!$C$15)+K151-L151 | N151: =ROUND(M151*(Assumptions!$C$19/Assumptions!$C$8), 2) | O151: =J151+K151-L151-N151 | P151: =O151+(Assumptions!$C$9-M151) | Q151: =P151-Assumptions!$C$10 | R151: =IF(Q151<Assumptions!$C$12, "ALERT TRIGGERED", "COMPLIANT")
A152: TOTAL / BENCHMARKS | C152: =SUM(C2:C151) | D152: =SUM(D2:D151) | F152: =SUM(F2:F151) | I152: =SUM(I2:I151) | K152: =SUM(K2:K151) | L152: =SUM(L2:L151) | M152: =MAX(M2:M151) | N152: =SUM(N2:N151) | O152: =O151 | P152: =P151 | Q152: =Q151

Sheet Working_Capital_DFO
A1: Ledger Date | B1: Settlements Receivable (Asset) | C1: Customers Payable (Liability) | D1: Net Settlement Float Gap | E1: Days Float Outstanding (DFO)
A2: =Data_Feed_Daily!A2 | B2: =Data_Feed_Daily!H2 | C2: =Data_Feed_Daily!I2 | D2: =B2-C2 | E2: =ROUND(B2/(Assumptions!$C$5*Assumptions!$C$6/365), 2)
A3: =Data_Feed_Daily!A3 | B3: =Data_Feed_Daily!H3 | C3: =Data_Feed_Daily!I3 | D3: =B3-C3 | E3: =ROUND(B3/(Assumptions!$C$5*Assumptions!$C$6/365), 2)
A4: =Data_Feed_Daily!A4 | B4: =Data_Feed_Daily!H4 | C4: =Data_Feed_Daily!I4 | D4: =B4-C4 | E4: =ROUND(B4/(Assumptions!$C$5*Assumptions!$C$6/365), 2)
A5: =Data_Feed_Daily!A5 | B5: =Data_Feed_Daily!H5 | C5: =Data_Feed_Daily!I5 | D5: =B5-C5 | E5: =ROUND(B5/(Assumptions!$C$5*Assumptions!$C$6/365), 2)
A6: =Data_Feed_Daily!A6 | B6: =Data_Feed_Daily!H6 | C6: =Data_Feed_Daily!I6 | D6: =B6-C6 | E6: =ROUND(B6/(Assumptions!$C$5*Assumptions!$C$6/365), 2)
A7: =Data_Feed_Daily!A7 | B7: =Data_Feed_Daily!H7 | C7: =Data_Feed_Daily!I7 | D7: =B7-C7 | E7: =ROUND(B7/(Assumptions!$C$5*Assumptions!$C$6/365), 2)
A8: =Data_Feed_Daily!A8 | B8: =Data_Feed_Daily!H8 | C8: =Data_Feed_Daily!I8 | D8: =B8-C8 | E8: =ROUND(B8/(Assumptions!$C$5*Assumptions!$C$6/365), 2)
A9: =Data_Feed_Daily!A9 | B9: =Data_Feed_Daily!H9 | C9: =Data_Feed_Daily!I9 | D9: =B9-C9 | E9: =ROUND(B9/(Assumptions!$C$5*Assumptions!$C$6/365), 2)
A10: =Data_Feed_Daily!A10 | B10: =Data_Feed_Daily!H10 | C10: =Data_Feed_Daily!I10 | D10: =B10-C10 | E10: =ROUND(B10/(Assumptions!$C$5*Assumptions!$C$6/365), 2)
A11: =Data_Feed_Daily!A11 | B11: =Data_Feed_Daily!H11 | C11: =Data_Feed_Daily!I11 | D11: =B11-C11 | E11: =ROUND(B11/(Assumptions!$C$5*Assumptions!$C$6/365), 2)
A12: =Data_Feed_Daily!A12 | B12: =Data_Feed_Daily!H12 | C12: =Data_Feed_Daily!I12 | D12: =B12-C12 | E12: =ROUND(B12/(Assumptions!$C$5*Assumptions!$C$6/365), 2)
A13: =Data_Feed_Daily!A13 | B13: =Data_Feed_Daily!H13 | C13: =Data_Feed_Daily!I13 | D13: =B13-C13 | E13: =ROUND(B13/(Assumptions!$C$5*Assumptions!$C$6/365), 2)
... A151: =Data_Feed_Daily!A151 | B151: =Data_Feed_Daily!H151 | C151: =Data_Feed_Daily!I151 | D151: =B151-C151 | E151: =ROUND(B151/(Assumptions!$C$5*Assumptions!$C$6/365), 2)
A152: AVERAGE / HORIZON PEAK | B152: =MAX(B2:B151) | C152: =MAX(C2:C151) | D152: =AVERAGE(D2:D151) | E152: =AVERAGE(E2:E151)

Sheet Regulatory_Liquidity_CECL
A1: Ledger Date | B1: Total HQLA Level 1 (Cash) | C1: Stressed 30d Outflows (30% overlay) | D1: Basel III LCR Ratio | E1: Compliance Status | F1: Daily Authorized GPV | G1: Daily CECL Credit Loss Provision | H1: Cumulative CECL Credit Allowance
A2: ='Daily_Cash_Waterfall'!A2 | B2: ='Daily_Cash_Waterfall'!O2 | C2: =ROUND(AVERAGE('Daily_Cash_Waterfall'!$D$2:D2)*30*Assumptions!$C$22, 2) | D2: =IF(C2>0, B2/C2, 999.0) | E2: =IF(D2>=Assumptions!$C$23, "COMPLIANT", IF(D2>=Assumptions!$C$24, "WARNING", "BREACH")) | F2: =Data_Feed_Daily!B2 | G2: =ROUND(F2*Assumptions!$C$20*Assumptions!$C$21, 2) | H2: =SUM($G$2:G2)
A3: ='Daily_Cash_Waterfall'!A3 | B3: ='Daily_Cash_Waterfall'!O3 | C3: =ROUND(AVERAGE('Daily_Cash_Waterfall'!$D$2:D3)*30*Assumptions!$C$22, 2) | D3: =IF(C3>0, B3/C3, 999.0) | E3: =IF(D3>=Assumptions!$C$23, "COMPLIANT", IF(D3>=Assumptions!$C$24, "WARNING", "BREACH")) | F3: =Data_Feed_Daily!B3 | G3: =ROUND(F3*Assumptions!$C$20*Assumptions!$C$21, 2) | H3: =SUM($G$2:G3)
A4: ='Daily_Cash_Waterfall'!A4 | B4: ='Daily_Cash_Waterfall'!O4 | C4: =ROUND(AVERAGE('Daily_Cash_Waterfall'!$D$2:D4)*30*Assumptions!$C$22, 2) | D4: =IF(C4>0, B4/C4, 999.0) | E4: =IF(D4>=Assumptions!$C$23, "COMPLIANT", IF(D4>=Assumptions!$C$24, "WARNING", "BREACH")) | F4: =Data_Feed_Daily!B4 | G4: =ROUND(F4*Assumptions!$C$20*Assumptions!$C$21, 2) | H4: =SUM($G$2:G4)
A5: ='Daily_Cash_Waterfall'!A5 | B5: ='Daily_Cash_Waterfall'!O5 | C5: =ROUND(AVERAGE('Daily_Cash_Waterfall'!$D$2:D5)*30*Assumptions!$C$22, 2) | D5: =IF(C5>0, B5/C5, 999.0) | E5: =IF(D5>=Assumptions!$C$23, "COMPLIANT", IF(D5>=Assumptions!$C$24, "WARNING", "BREACH")) | F5: =Data_Feed_Daily!B5 | G5: =ROUND(F5*Assumptions!$C$20*Assumptions!$C$21, 2) | H5: =SUM($G$2:G5)
A6: ='Daily_Cash_Waterfall'!A6 | B6: ='Daily_Cash_Waterfall'!O6 | C6: =ROUND(AVERAGE('Daily_Cash_Waterfall'!$D$2:D6)*30*Assumptions!$C$22, 2) | D6: =IF(C6>0, B6/C6, 999.0) | E6: =IF(D6>=Assumptions!$C$23, "COMPLIANT", IF(D6>=Assumptions!$C$24, "WARNING", "BREACH")) | F6: =Data_Feed_Daily!B6 | G6: =ROUND(F6*Assumptions!$C$20*Assumptions!$C$21, 2) | H6: =SUM($G$2:G6)
A7: ='Daily_Cash_Waterfall'!A7 | B7: ='Daily_Cash_Waterfall'!O7 | C7: =ROUND(AVERAGE('Daily_Cash_Waterfall'!$D$2:D7)*30*Assumptions!$C$22, 2) | D7: =IF(C7>0, B7/C7, 999.0) | E7: =IF(D7>=Assumptions!$C$23, "COMPLIANT", IF(D7>=Assumptions!$C$24, "WARNING", "BREACH")) | F7: =Data_Feed_Daily!B7 | G7: =ROUND(F7*Assumptions!$C$20*Assumptions!$C$21, 2) | H7: =SUM($G$2:G7)
A8: ='Daily_Cash_Waterfall'!A8 | B8: ='Daily_Cash_Waterfall'!O8 | C8: =ROUND(AVERAGE('Daily_Cash_Waterfall'!$D$2:D8)*30*Assumptions!$C$22, 2) | D8: =IF(C8>0, B8/C8, 999.0) | E8: =IF(D8>=Assumptions!$C$23, "COMPLIANT", IF(D8>=Assumptions!$C$24, "WARNING", "BREACH")) | F8: =Data_Feed_Daily!B8 | G8: =ROUND(F8*Assumptions!$C$20*Assumptions!$C$21, 2) | H8: =SUM($G$2:G8)
A9: ='Daily_Cash_Waterfall'!A9 | B9: ='Daily_Cash_Waterfall'!O9 | C9: =ROUND(AVERAGE('Daily_Cash_Waterfall'!$D$2:D9)*30*Assumptions!$C$22, 2) | D9: =IF(C9>0, B9/C9, 999.0) | E9: =IF(D9>=Assumptions!$C$23, "COMPLIANT", IF(D9>=Assumptions!$C$24, "WARNING", "BREACH")) | F9: =Data_Feed_Daily!B9 | G9: =ROUND(F9*Assumptions!$C$20*Assumptions!$C$21, 2) | H9: =SUM($G$2:G9)
A10: ='Daily_Cash_Waterfall'!A10 | B10: ='Daily_Cash_Waterfall'!O10 | C10: =ROUND(AVERAGE('Daily_Cash_Waterfall'!$D$2:D10)*30*Assumptions!$C$22, 2) | D10: =IF(C10>0, B10/C10, 999.0) | E10: =IF(D10>=Assumptions!$C$23, "COMPLIANT", IF(D10>=Assumptions!$C$24, "WARNING", "BREACH")) | F10: =Data_Feed_Daily!B10 | G10: =ROUND(F10*Assumptions!$C$20*Assumptions!$C$21, 2) | H10: =SUM($G$2:G10)
A11: ='Daily_Cash_Waterfall'!A11 | B11: ='Daily_Cash_Waterfall'!O11 | C11: =ROUND(AVERAGE('Daily_Cash_Waterfall'!$D$2:D11)*30*Assumptions!$C$22, 2) | D11: =IF(C11>0, B11/C11, 999.0) | E11: =IF(D11>=Assumptions!$C$23, "COMPLIANT", IF(D11>=Assumptions!$C$24, "WARNING", "BREACH")) | F11: =Data_Feed_Daily!B11 | G11: =ROUND(F11*Assumptions!$C$20*Assumptions!$C$21, 2) | H11: =SUM($G$2:G11)
A12: ='Daily_Cash_Waterfall'!A12 | B12: ='Daily_Cash_Waterfall'!O12 | C12: =ROUND(AVERAGE('Daily_Cash_Waterfall'!$D$2:D12)*30*Assumptions!$C$22, 2) | D12: =IF(C12>0, B12/C12, 999.0) | E12: =IF(D12>=Assumptions!$C$23, "COMPLIANT", IF(D12>=Assumptions!$C$24, "WARNING", "BREACH")) | F12: =Data_Feed_Daily!B12 | G12: =ROUND(F12*Assumptions!$C$20*Assumptions!$C$21, 2) | H12: =SUM($G$2:G12)
A13: ='Daily_Cash_Waterfall'!A13 | B13: ='Daily_Cash_Waterfall'!O13 | C13: =ROUND(AVERAGE('Daily_Cash_Waterfall'!$D$2:D13)*30*Assumptions!$C$22, 2) | D13: =IF(C13>0, B13/C13, 999.0) | E13: =IF(D13>=Assumptions!$C$23, "COMPLIANT", IF(D13>=Assumptions!$C$24, "WARNING", "BREACH")) | F13: =Data_Feed_Daily!B13 | G13: =ROUND(F13*Assumptions!$C$20*Assumptions!$C$21, 2) | H13: =SUM($G$2:G13)
... A151: ='Daily_Cash_Waterfall'!A151 | B151: ='Daily_Cash_Waterfall'!O151 | C151: =ROUND(AVERAGE('Daily_Cash_Waterfall'!$D$2:D151)*30*Assumptions!$C$22, 2) | D151: =IF(C151>0, B151/C151, 999.0) | E151: =IF(D151>=Assumptions!$C$23, "COMPLIANT", IF(D151>=Assumptions!$C$24, "WARNING", "BREACH")) | F151: =Data_Feed_Daily!B151 | G151: =ROUND(F151*Assumptions!$C$20*Assumptions!$C$21, 2) | H151: =SUM($G$2:G151)
A152: AVERAGE / PERIOD TOTAL | B152: =AVERAGE(B2:B151) | C152: =AVERAGE(C2:C151) | D152: =AVERAGE(D2:D151) | E152: =IF(D152>=Assumptions!$C$23, "COMPLIANT", "BREACH") | F152: =SUM(F2:F151) | G152: =SUM(G2:G151) | H152: =H151

Sheet TWCF_13W_Bridge
A1: ISO Week | B1: Actual Net Cash Flow | C1: Budget Net Cash Flow | D1: Net Variance Delta | E1: Volume Outperformance | F1: Card Mix Substitution | G1: Clearing Timing Friction | H1: CECL Provision Drag | I1: Residual Epsilon | J1: Bridge Total Sum | K1: Additive Reconciliation Identity Check
A2: 2026-W01 | B2: -5.868943e+08 | C2: 21468000 | D2: =B2-C2 | E2: -15604152 | F2: 19213.41 | G2: 0 | H2: -655544.73 | I2: -5.9277736e+08 | J2: =SUM(E2:I2) | K2: =IF(ABS(J2-D2)<1.0, "EXACT MATCH (VERIFIED)", "RECONCILIATION ERROR")
A3: 2026-W02 | B3: 1.3141255e+08 | C3: 37569000 | D3: =B3-C3 | E3: 4517150.1 | F3: -1117481.6 | G3: 0 | H3: -4704991.6 | I3: 90443885 | J3: =SUM(E3:I3) | K3: =IF(ABS(J3-D3)<1.0, "EXACT MATCH (VERIFIED)", "RECONCILIATION ERROR")
A4: 2026-W03 | B4: 2.6204841e+08 | C4: 37569000 | D4: =B4-C4 | E4: 5124088.8 | F4: -56221.49 | G4: 0 | H4: -4772843.9 | I4: 2.1941154e+08 | J4: =SUM(E4:I4) | K4: =IF(ABS(J4-D4)<1.0, "EXACT MATCH (VERIFIED)", "RECONCILIATION ERROR")
A5: 2026-W04 | B5: 2.6837963e+08 | C5: 37569000 | D5: =B5-C5 | E5: 4727804.5 | F5: 18997.54 | G5: 0 | H5: -4728541.6 | I5: 2.2606383e+08 | J5: =SUM(E5:I5) | K5: =IF(ABS(J5-D5)<1.0, "EXACT MATCH (VERIFIED)", "RECONCILIATION ERROR")
A6: 2026-W05 | B6: 2.5919527e+08 | C6: 37569000 | D6: =B6-C6 | E6: 5004562.5 | F6: -76840.4 | G6: 0 | H6: -4759481.6 | I6: 2.1669855e+08 | J6: =SUM(E6:I6) | K6: =IF(ABS(J6-D6)<1.0, "EXACT MATCH (VERIFIED)", "RECONCILIATION ERROR")
A7: 2026-W06 | B7: 2.6446991e+08 | C7: 37569000 | D7: =B7-C7 | E7: 5274686.5 | F7: -44866 | G7: 0 | H7: -4789679.9 | I7: 2.2167109e+08 | J7: =SUM(E7:I7) | K7: =IF(ABS(J7-D7)<1.0, "EXACT MATCH (VERIFIED)", "RECONCILIATION ERROR")
A8: 2026-W07 | B8: 2.842403e+08 | C8: 37569000 | D8: =B8-C8 | E8: 4783200.1 | F8: 164107.67 | G8: 0 | H8: -4734734.5 | I8: 2.4172399e+08 | J8: =SUM(E8:I8) | K8: =IF(ABS(J8-D8)<1.0, "EXACT MATCH (VERIFIED)", "RECONCILIATION ERROR")
A9: 2026-W08 | B9: 2.5977633e+08 | C9: 37569000 | D9: =B9-C9 | E9: 5210224.4 | F9: -84215.99 | G9: 0 | H9: -4782473.4 | I9: 2.1708133e+08 | J9: =SUM(E9:I9) | K9: =IF(ABS(J9-D9)<1.0, "EXACT MATCH (VERIFIED)", "RECONCILIATION ERROR")
A10: 2026-W09 | B10: 2.6479897e+08 | C10: 37569000 | D10: =B10-C10 | E10: 4546105.5 | F10: -3808.37 | G10: 0 | H10: -4708228.7 | I10: 2.2268767e+08 | J10: =SUM(E10:I10) | K10: =IF(ABS(J10-D10)<1.0, "EXACT MATCH (VERIFIED)", "RECONCILIATION ERROR")
A11: 2026-W10 | B11: 2.5984729e+08 | C11: 37569000 | D11: =B11-C11 | E11: 4859458 | F11: -61723.03 | G11: 0 | H11: -4743259.7 | I11: 2.1748056e+08 | J11: =SUM(E11:I11) | K11: =IF(ABS(J11-D11)<1.0, "EXACT MATCH (VERIFIED)", "RECONCILIATION ERROR")
A12: 2026-W11 | B12: 3.0324073e+08 | C12: 37569000 | D12: =B12-C12 | E12: 4870968.5 | F12: 331209.47 | G12: 0 | H12: -4744546.5 | I12: 2.6046955e+08 | J12: =SUM(E12:I12) | K12: =IF(ABS(J12-D12)<1.0, "EXACT MATCH (VERIFIED)", "RECONCILIATION ERROR")
A13: 2026-W12 | B13: 2.3688499e+08 | C13: 37569000 | D13: =B13-C13 | E13: 4641282.4 | F13: -261506.78 | G13: 0 | H13: -4718868.9 | I13: 1.9493622e+08 | J13: =SUM(E13:I13) | K13: =IF(ABS(J13-D13)<1.0, "EXACT MATCH (VERIFIED)", "RECONCILIATION ERROR")
... A23: 2026-W22 | B23: 2.6662528e+08 | C23: 32202000 | D23: =B23-C23 | E23: 9454169.7 | F23: 33002.11 | G23: 0 | H23: -4656922.3 | I23: 2.2493611e+08 | J23: =SUM(E23:I23) | K23: =IF(ABS(J23-D23)<1.0, "EXACT MATCH (VERIFIED)", "RECONCILIATION ERROR")
A24: CUMULATIVE 13W TOTAL | B24: =SUM(B2:B23) | C24: =SUM(C2:C23) | D24: =SUM(D2:D23) | E24: =SUM(E2:E23) | F24: =SUM(F2:F23) | G24: =SUM(G2:G23) | H24: =SUM(H2:H23) | I24: =SUM(I2:I23) | J24: =SUM(J2:J23) | K24: =IF(ABS(J24-D24)<1.0, "EXACT MATCH (VERIFIED)", "RECONCILIATION ERROR")
